<robot name="robot">
    <link name="map"/>
    <link name="base">
        <visual>
            <geometry>
                <mesh filename="package://eye_on_you/meshes/base.stl" />
            </geometry>
        </visual>
        <collision>
            <geometry>
                <mesh filename="package://eye_on_you/meshes/base.stl" />
            </geometry>
        </collision>
    </link>
    <link name="home">
        <visual>
            <origin xyz="-1.47 -31.7 40.5" />  
            <geometry>
                <mesh filename="package://eye_on_you/meshes/home.stl" />
            </geometry>
        </visual>
        <collision>
            <origin xyz="-1.47 -31.7 40.5" />  
            <geometry>
                <mesh filename="package://eye_on_you/meshes/home.stl" />
            </geometry>
        </collision>
    </link>
    <link name="arm">
        <visual>
            <origin xyz="14.17 -89.3 99.4" /> 
            <geometry>
                <mesh filename="package://eye_on_you/meshes/arm.stl" />
            </geometry>
        </visual>
        <collision>
            <origin xyz="14.17 -89.3 99.4" />  
            <geometry>
                <mesh filename="package://eye_on_you/meshes/arm.stl" />
            </geometry>
        </collision>
    </link>

    <joint name="world_robot_joint" type="fixed">
        <axis xyz="0 0 1" />
        <origin xyz="0 0 0"/>
        <parent link="map"/>
        <child link="base"/>
    </joint>

    <joint name="base_home_joint" type="revolute">
        <axis xyz="0 1 0" />
        <limit lower="-0.7853" upper="0.7853" effort="1000.0" velocity="0.5"/>
        <origin xyz="1.47 31.7 -40.5"/>  <!-- Changed center of rotation -->
        <parent link="base"/>
        <child link="home"/>
    </joint>

    <joint name="home_arm_joint" type="revolute">
        <axis xyz="1 0 0" />
        <limit lower="-1.57" upper="1.0" effort="1000.0" velocity="0.5"/>
        <origin rpy="0 0 0" xyz="-12 57.6 -58.9"/>  
        <parent link="home"/>
        <child link="arm"/>
    </joint>

</robot>    